2019-03-25 20:56:00,237 root INFO Dividing 5 by 0
2019-03-25 20:56:00,237 root ERROR Error running task
Traceback (most recent call last):
  File "task_with_error_handling_step4.py", line 37, in <module>
    main(args.n1, args.n2, args.output)
  File "task_with_error_handling_step4.py", line 11, in main
    result = number/other_number
ZeroDivisionError: division by zero
2019-03-25 20:56:20,247 root INFO Dividing 5 by 0
2019-03-25 20:56:20,247 root ERROR Error running task
Traceback (most recent call last):
  File "task_with_error_handling_step4.py", line 37, in <module>
    main(args.n1, args.n2, args.output)
  File "task_with_error_handling_step4.py", line 11, in main
    result = number/other_number
ZeroDivisionError: division by zero
2019-03-27 17:54:08,461 root INFO Dividing 10 by 0
2019-03-27 17:54:08,461 root ERROR Error running task
Traceback (most recent call last):
  File "task_with_error_handling_step4.py", line 37, in <module>
    main(args.n1, args.n2, args.output)
  File "task_with_error_handling_step4.py", line 11, in main
    result = number/other_number
ZeroDivisionError: division by zero
